Workbook

Sheet All Saints
A1: Electorate (registered electors) | B1: 3495
A2: Councillors elected in ward | B2: 1
A3: Turnout | B3: 0.2761
A4: Blank / invalid ballots (rejected) | B4: 5
C5: 2023 result | F5: Prediction based on national swing since May 2023
A6: Candidate | B6: Party | C6: Votes | D6: % of votes | E6: % of electors | F6: votes | G6: % of electorate
A7: Kier Dorran Kemp | B7: Labour Party | C7: 118 | D7: =C7*100/SUM($C$7:$C$13) -> 12.291667 | E7: =C7*100/$B$1 -> 3.3762518 | F7: =C7*IF(ISNUMBER(SEARCH("Labour",B7)),National!$L$4,IF(ISNUMBER(SEARCH("Conservative",B7)),National!$L$5,IF(OR(ISNUMBER(SEARCH("Reform",B7)),ISNUMBER(SEARCH("RefUK",B7))),National!$L$6,IF(ISNUMBER(SEARCH("Green",B7)),National!$L$7,IF(OR(ISNUMBER(SEARCH("Liberal Democrat",B7)),ISNUMBER(SEARCH("Lib Dem",B7))),National!$L$8,National!$L$9))))) -> 46.651163 | G7: =F7*100/$B$1 -> 1.3347972
A8: Habeeb Adeyemi Ogunfemi (commonly known as Harold Ogunfemi) | B8: Local Conservatives | C8: 190 | D8: =C8*100/SUM($C$7:$C$13) -> 19.791667 | E8: =C8*100/$B$1 -> 5.4363376 | F8: =C8*IF(ISNUMBER(SEARCH("Labour",B8)),National!$L$4,IF(ISNUMBER(SEARCH("Conservative",B8)),National!$L$5,IF(OR(ISNUMBER(SEARCH("Reform",B8)),ISNUMBER(SEARCH("RefUK",B8))),National!$L$6,IF(ISNUMBER(SEARCH("Green",B8)),National!$L$7,IF(OR(ISNUMBER(SEARCH("Liberal Democrat",B8)),ISNUMBER(SEARCH("Lib Dem",B8))),National!$L$8,National!$L$9))))) -> 124.23077 | G8: =F8*100/$B$1 -> 3.5545284
A9: Bernard Edward Hyde | B9: Green Party | C9: 34 | D9: =C9*100/SUM($C$7:$C$13) -> 3.5416667 | E9: =C9*100/$B$1 -> 0.97281831 | F9: =C9*IF(ISNUMBER(SEARCH("Labour",B9)),National!$L$4,IF(ISNUMBER(SEARCH("Conservative",B9)),National!$L$5,IF(OR(ISNUMBER(SEARCH("Reform",B9)),ISNUMBER(SEARCH("RefUK",B9))),National!$L$6,IF(ISNUMBER(SEARCH("Green",B9)),National!$L$7,IF(OR(ISNUMBER(SEARCH("Liberal Democrat",B9)),ISNUMBER(SEARCH("Lib Dem",B9))),National!$L$8,National!$L$9))))) -> 80.75 | G9: =F9*100/$B$1 -> 2.3104435
A10: Elizabeth Ann Simpson | B10: Liberal Democrats | C10: 22 | D10: =C10*100/SUM($C$7:$C$13) -> 2.2916667 | E10: =C10*100/$B$1 -> 0.62947067 | F10: =C10*IF(ISNUMBER(SEARCH("Labour",B10)),National!$L$4,IF(ISNUMBER(SEARCH("Conservative",B10)),National!$L$5,IF(OR(ISNUMBER(SEARCH("Reform",B10)),ISNUMBER(SEARCH("RefUK",B10))),National!$L$6,IF(ISNUMBER(SEARCH("Green",B10)),National!$L$7,IF(OR(ISNUMBER(SEARCH("Liberal Democrat",B10)),ISNUMBER(SEARCH("Lib Dem",B10))),National!$L$8,National!$L$9))))) -> 30.8 | G10: =F10*100/$B$1 -> 0.88125894
A11: Harjinder Singh Khatkar (commonly known as Bill Khatkar) | B11: Reform UK | C11: 49 | D11: =C11*100/SUM($C$7:$C$13) -> 5.1041667 | E11: =C11*100/$B$1 -> 1.4020029 | F11: =C11*IF(ISNUMBER(SEARCH("Labour",B11)),National!$L$4,IF(ISNUMBER(SEARCH("Conservative",B11)),National!$L$5,IF(OR(ISNUMBER(SEARCH("Reform",B11)),ISNUMBER(SEARCH("RefUK",B11))),National!$L$6,IF(ISNUMBER(SEARCH("Green",B11)),National!$L$7,IF(OR(ISNUMBER(SEARCH("Liberal Democrat",B11)),ISNUMBER(SEARCH("Lib Dem",B11))),National!$L$8,National!$L$9))))) -> 204.16667 | G11: =F11*100/$B$1 -> 5.8416786
A12: Christopher Stuart Spalding (commonly known as Chris Spalding) | B12: Independent | C12: 295 | D12: =C12*100/SUM($C$7:$C$13) -> 30.729167 | E12: =C12*100/$B$1 -> 8.4406295 | F12: =C12*IF(ISNUMBER(SEARCH("Labour",B12)),National!$L$4,IF(ISNUMBER(SEARCH("Conservative",B12)),National!$L$5,IF(OR(ISNUMBER(SEARCH("Reform",B12)),ISNUMBER(SEARCH("RefUK",B12))),National!$L$6,IF(ISNUMBER(SEARCH("Green",B12)),National!$L$7,IF(OR(ISNUMBER(SEARCH("Liberal Democrat",B12)),ISNUMBER(SEARCH("Lib Dem",B12))),National!$L$8,National!$L$9))))) -> 337.14286 | G12: =F12*100/$B$1 -> 9.6464337
A13: Julie Wallace | B13: Independent | C13: 252 | D13: =C13*100/SUM($C$7:$C$13) -> 26.25 | E13: =C13*100/$B$1 -> 7.2103004 | F13: =C13*IF(ISNUMBER(SEARCH("Labour",B13)),National!$L$4,IF(ISNUMBER(SEARCH("Conservative",B13)),National!$L$5,IF(OR(ISNUMBER(SEARCH("Reform",B13)),ISNUMBER(SEARCH("RefUK",B13))),National!$L$6,IF(ISNUMBER(SEARCH("Green",B13)),National!$L$7,IF(OR(ISNUMBER(SEARCH("Liberal Democrat",B13)),ISNUMBER(SEARCH("Lib Dem",B13))),National!$L$8,National!$L$9))))) -> 288 | G13: =F13*100/$B$1 -> 8.2403433

Sheet Chatham Central & Brompton
A1: Electorate (registered electors) | B1: 10525
A2: Councillors elected in ward | B2: 3
A3: Turnout | B3: 0.2091
A4: Blank / invalid ballots (rejected) | B4: 21
C5: 2023 result | F5: Prediction based on national swing since May 2023
A6: Candidate | B6: Party | C6: Votes | D6: % of votes | E6: % of electors | F6: votes | G6: % of electorate
A7: Vince Maple (Vincent Stewart Maple; commonly known as Vince Maple) | B7: Labour and Co-operative Party | C7: 1394 | D7: =C7*100/SUM($C$7:$C$14) -> 23.595125 | E7: =C7*100/$B$1 -> 13.244656 | F7: =C7*IF(ISNUMBER(SEARCH("Labour",B7)),National!$L$4,IF(ISNUMBER(SEARCH("Conservative",B7)),National!$L$5,IF(OR(ISNUMBER(SEARCH("Reform",B7)),ISNUMBER(SEARCH("RefUK",B7))),National!$L$6,IF(ISNUMBER(SEARCH("Green",B7)),National!$L$7,IF(OR(ISNUMBER(SEARCH("Liberal Democrat",B7)),ISNUMBER(SEARCH("Lib Dem",B7))),National!$L$8,National!$L$9))))) -> 551.11628 | G7: =F7*100/$B$1 -> 5.2362592
A8: Nina Gurung | B8: Labour and Co-operative Party | C8: 1211 | D8: =C8*100/SUM($C$7:$C$14) -> 20.49763 | E8: =C8*100/$B$1 -> 11.505938 | F8: =C8*IF(ISNUMBER(SEARCH("Labour",B8)),National!$L$4,IF(ISNUMBER(SEARCH("Conservative",B8)),National!$L$5,IF(OR(ISNUMBER(SEARCH("Reform",B8)),ISNUMBER(SEARCH("RefUK",B8))),National!$L$6,IF(ISNUMBER(SEARCH("Green",B8)),National!$L$7,IF(OR(ISNUMBER(SEARCH("Liberal Democrat",B8)),ISNUMBER(SEARCH("Lib Dem",B8))),National!$L$8,National!$L$9))))) -> 478.76744 | G8: =F8*100/$B$1 -> 4.5488593
A9: Shakirat Oyindamola Animashaun (commonly known as Damola Animashaun) | B9: Labour and Co-operative Party | C9: 1136 | D9: =C9*100/SUM($C$7:$C$14) -> 19.228165 | E9: =C9*100/$B$1 -> 10.793349 | F9: =C9*IF(ISNUMBER(SEARCH("Labour",B9)),National!$L$4,IF(ISNUMBER(SEARCH("Conservative",B9)),National!$L$5,IF(OR(ISNUMBER(SEARCH("Reform",B9)),ISNUMBER(SEARCH("RefUK",B9))),National!$L$6,IF(ISNUMBER(SEARCH("Green",B9)),National!$L$7,IF(OR(ISNUMBER(SEARCH("Liberal Democrat",B9)),ISNUMBER(SEARCH("Lib Dem",B9))),National!$L$8,National!$L$9))))) -> 449.11628 | G9: =F9*100/$B$1 -> 4.267138
A10: Vrinderpal Singh Khera (commonly known as Paul Khera) | B10: Local Conservatives | C10: 552 | D10: =C10*100/SUM($C$7:$C$14) -> 9.3432634 | E10: =C10*100/$B$1 -> 5.2446556 | F10: =C10*IF(ISNUMBER(SEARCH("Labour",B10)),National!$L$4,IF(ISNUMBER(SEARCH("Conservative",B10)),National!$L$5,IF(OR(ISNUMBER(SEARCH("Reform",B10)),ISNUMBER(SEARCH("RefUK",B10))),National!$L$6,IF(ISNUMBER(SEARCH("Green",B10)),National!$L$7,IF(OR(ISNUMBER(SEARCH("Liberal Democrat",B10)),ISNUMBER(SEARCH("Lib Dem",B10))),National!$L$8,National!$L$9))))) -> 360.92308 | G10: =F10*100/$B$1 -> 3.4291979
A11: Claude Jenner Granville King | B11: Local Conservatives | C11: 517 | D11: =C11*100/SUM($C$7:$C$14) -> 8.7508463 | E11: =C11*100/$B$1 -> 4.912114 | F11: =C11*IF(ISNUMBER(SEARCH("Labour",B11)),National!$L$4,IF(ISNUMBER(SEARCH("Conservative",B11)),National!$L$5,IF(OR(ISNUMBER(SEARCH("Reform",B11)),ISNUMBER(SEARCH("RefUK",B11))),National!$L$6,IF(ISNUMBER(SEARCH("Green",B11)),National!$L$7,IF(OR(ISNUMBER(SEARCH("Liberal Democrat",B11)),ISNUMBER(SEARCH("Lib Dem",B11))),National!$L$8,National!$L$9))))) -> 338.03846 | G11: =F11*100/$B$1 -> 3.2117669
A12: Habib Odunlamin Tejan | B12: Local Conservatives | C12: 467 | D12: =C12*100/SUM($C$7:$C$14) -> 7.9045362 | E12: =C12*100/$B$1 -> 4.4370546 | F12: =C12*IF(ISNUMBER(SEARCH("Labour",B12)),National!$L$4,IF(ISNUMBER(SEARCH("Conservative",B12)),National!$L$5,IF(OR(ISNUMBER(SEARCH("Reform",B12)),ISNUMBER(SEARCH("RefUK",B12))),National!$L$6,IF(ISNUMBER(SEARCH("Green",B12)),National!$L$7,IF(OR(ISNUMBER(SEARCH("Liberal Democrat",B12)),ISNUMBER(SEARCH("Lib Dem",B12))),National!$L$8,National!$L$9))))) -> 305.34615 | G12: =F12*100/$B$1 -> 2.9011511
A13: Robert Gerald Edward O'Hanlon (commonly known as Rob O'Hanlon) | B13: Green Party | C13: 336 | D13: =C13*100/SUM($C$7:$C$14) -> 5.6872038 | E13: =C13*100/$B$1 -> 3.192399 | F13: =C13*IF(ISNUMBER(SEARCH("Labour",B13)),National!$L$4,IF(ISNUMBER(SEARCH("Conservative",B13)),National!$L$5,IF(OR(ISNUMBER(SEARCH("Reform",B13)),ISNUMBER(SEARCH("RefUK",B13))),National!$L$6,IF(ISNUMBER(SEARCH("Green",B13)),National!$L$7,IF(OR(ISNUMBER(SEARCH("Liberal Democrat",B13)),ISNUMBER(SEARCH("Lib Dem",B13))),National!$L$8,National!$L$9))))) -> 798 | G13: =F13*100/$B$1 -> 7.5819477
A14: Geoffrey William Juby (commonly known as Geoff Juby) | B14: Liberal Democrats | C14: 295 | D14: =C14*100/SUM($C$7:$C$14) -> 4.9932295 | E14: =C14*100/$B$1 -> 2.8028504 | F14: =C14*IF(ISNUMBER(SEARCH("Labour",B14)),National!$L$4,IF(ISNUMBER(SEARCH("Conservative",B14)),National!$L$5,IF(OR(ISNUMBER(SEARCH("Reform",B14)),ISNUMBER(SEARCH("RefUK",B14))),National!$L$6,IF(ISNUMBER(SEARCH("Green",B14)),National!$L$7,IF(OR(ISNUMBER(SEARCH("Liberal Democrat",B14)),ISNUMBER(SEARCH("Lib Dem",B14))),National!$L$8,National!$L$9))))) -> 413 | G14: =F14*100/$B$1 -> 3.9239905

Sheet Cuxton, Halling & Riverside
A1: Electorate (registered electors) | B1: 6129
A2: Councillors elected in ward | B2: 2
A3: Turnout | B3: 0.3092
A4: Blank / invalid ballots (rejected) | B4: 16
F5: prediction based in national swing since May 2023
A6: Candidate | B6: Party | C6: Votes | D6: % of votes | E6: % of electors | F6: votes | G6: % of electorate
A7: Stephen Joseph Donald McCormack | B7: Labour Party | C7: 414 | D7: =C7*100/SUM($C$7:$C$13) -> 11.480865 | E7: =C7*100/$B$1 -> 6.7547724 | F7: =C7*IF(ISNUMBER(SEARCH("Labour",B7)),National!$L$4,IF(ISNUMBER(SEARCH("Conservative",B7)),National!$L$5,IF(OR(ISNUMBER(SEARCH("Reform",B7)),ISNUMBER(SEARCH("RefUK",B7))),National!$L$6,IF(ISNUMBER(SEARCH("Green",B7)),National!$L$7,IF(OR(ISNUMBER(SEARCH("Liberal Democrat",B7)),ISNUMBER(SEARCH("Lib Dem",B7))),National!$L$8,National!$L$9))))) -> 163.67442 | G7: =F7*100/$B$1 -> 2.6704914
A8: Victoria Valerie Morris | B8: Labour Party | C8: 408 | D8: =C8*100/SUM($C$7:$C$13) -> 11.314476 | E8: =C8*100/$B$1 -> 6.6568771 | F8: =C8*IF(ISNUMBER(SEARCH("Labour",B8)),National!$L$4,IF(ISNUMBER(SEARCH("Conservative",B8)),National!$L$5,IF(OR(ISNUMBER(SEARCH("Reform",B8)),ISNUMBER(SEARCH("RefUK",B8))),National!$L$6,IF(ISNUMBER(SEARCH("Green",B8)),National!$L$7,IF(OR(ISNUMBER(SEARCH("Liberal Democrat",B8)),ISNUMBER(SEARCH("Lib Dem",B8))),National!$L$8,National!$L$9))))) -> 161.30233 | G8: =F8*100/$B$1 -> 2.6317886
A9: Matt Fearn (Matthew James Fearn; commonly known as Matt Fearn) | B9: Local Conservatives | C9: 880 | D9: =C9*100/SUM($C$7:$C$13) -> 24.403771 | E9: =C9*100/$B$1 -> 14.35797 | F9: =C9*IF(ISNUMBER(SEARCH("Labour",B9)),National!$L$4,IF(ISNUMBER(SEARCH("Conservative",B9)),National!$L$5,IF(OR(ISNUMBER(SEARCH("Reform",B9)),ISNUMBER(SEARCH("RefUK",B9))),National!$L$6,IF(ISNUMBER(SEARCH("Green",B9)),National!$L$7,IF(OR(ISNUMBER(SEARCH("Liberal Democrat",B9)),ISNUMBER(SEARCH("Lib Dem",B9))),National!$L$8,National!$L$9))))) -> 575.38462 | G9: =F9*100/$B$1 -> 9.3879037
A10: Phil Filmer (Phillip Filmer; commonly known as Phil Filmer) | B10: Local Conservatives | C10: 685 | D10: =C10*100/SUM($C$7:$C$13) -> 18.996118 | E10: =C10*100/$B$1 -> 11.176375 | F10: =C10*IF(ISNUMBER(SEARCH("Labour",B10)),National!$L$4,IF(ISNUMBER(SEARCH("Conservative",B10)),National!$L$5,IF(OR(ISNUMBER(SEARCH("Reform",B10)),ISNUMBER(SEARCH("RefUK",B10))),National!$L$6,IF(ISNUMBER(SEARCH("Green",B10)),National!$L$7,IF(OR(ISNUMBER(SEARCH("Liberal Democrat",B10)),ISNUMBER(SEARCH("Lib Dem",B10))),National!$L$8,National!$L$9))))) -> 447.88462 | G10: =F10*100/$B$1 -> 7.3076296
A11: Matt Nightingale (Matthew Richard Nightingale; commonly known as Matt Nightingale) | B11: Green Party | C11: 641 | D11: =C11*100/SUM($C$7:$C$13) -> 17.775929 | E11: =C11*100/$B$1 -> 10.458476 | F11: =C11*IF(ISNUMBER(SEARCH("Labour",B11)),National!$L$4,IF(ISNUMBER(SEARCH("Conservative",B11)),National!$L$5,IF(OR(ISNUMBER(SEARCH("Reform",B11)),ISNUMBER(SEARCH("RefUK",B11))),National!$L$6,IF(ISNUMBER(SEARCH("Green",B11)),National!$L$7,IF(OR(ISNUMBER(SEARCH("Liberal Democrat",B11)),ISNUMBER(SEARCH("Lib Dem",B11))),National!$L$8,National!$L$9))))) -> 1522.375 | G11: =F11*100/$B$1 -> 24.838881
A12: Cat Jamieson (Catriona Margaret Jamieson; commonly known as Cat Jamieson) | B12: Green Party | C12: 502 | D12: =C12*100/SUM($C$7:$C$13) -> 13.921242 | E12: =C12*100/$B$1 -> 8.1905694 | F12: =C12*IF(ISNUMBER(SEARCH("Labour",B12)),National!$L$4,IF(ISNUMBER(SEARCH("Conservative",B12)),National!$L$5,IF(OR(ISNUMBER(SEARCH("Reform",B12)),ISNUMBER(SEARCH("RefUK",B12))),National!$L$6,IF(ISNUMBER(SEARCH("Green",B12)),National!$L$7,IF(OR(ISNUMBER(SEARCH("Liberal Democrat",B12)),ISNUMBER(SEARCH("Lib Dem",B12))),National!$L$8,National!$L$9))))) -> 1192.25 | G12: =F12*100/$B$1 -> 19.452602
A13: Ron Gillett (Ronald Arcon Gillett; commonly known as Ron Gillett) | B13: Liberal Democrats | C13: 76 | D13: =C13*100/SUM($C$7:$C$13) -> 2.1075984 | E13: =C13*100/$B$1 -> 1.2400065 | F13: =C13*IF(ISNUMBER(SEARCH("Labour",B13)),National!$L$4,IF(ISNUMBER(SEARCH("Conservative",B13)),National!$L$5,IF(OR(ISNUMBER(SEARCH("Reform",B13)),ISNUMBER(SEARCH("RefUK",B13))),National!$L$6,IF(ISNUMBER(SEARCH("Green",B13)),National!$L$7,IF(OR(ISNUMBER(SEARCH("Liberal Democrat",B13)),ISNUMBER(SEARCH("Lib Dem",B13))),National!$L$8,National!$L$9))))) -> 106.4 | G13: =F13*100/$B$1 -> 1.7360091

Sheet Fort Horsted
A1: Electorate (registered electors) | B1: 3530
A2: Councillors elected in ward | B2: 1
A3: Turnout | B3: 0.3088
A4: Blank / invalid ballots (rejected) | B4: 8
F5: prediction based in national swing since May 2023
A6: Candidate | B6: Party | C6: Votes | D6: % of votes | E6: % of electors | F6: votes | G6: % of electorate
A7: Joseph Simon Murray | B7: Labour Party | C7: 212 | D7: =C7*100/SUM($C$7:$C$10) -> 19.593346 | E7: =C7*100/$B$1 -> 6.0056657 | F7: =C7*IF(ISNUMBER(SEARCH("Labour",B7)),National!$L$4,IF(ISNUMBER(SEARCH("Conservative",B7)),National!$L$5,IF(OR(ISNUMBER(SEARCH("Reform",B7)),ISNUMBER(SEARCH("RefUK",B7))),National!$L$6,IF(ISNUMBER(SEARCH("Green",B7)),National!$L$7,IF(OR(ISNUMBER(SEARCH("Liberal Democrat",B7)),ISNUMBER(SEARCH("Lib Dem",B7))),National!$L$8,National!$L$9))))) -> 83.813953 | G7: =F7*100/$B$1 -> 2.374333
A8: Trevor Anthony Clarke | B8: Local Conservatives | C8: 489 | D8: =C8*100/SUM($C$7:$C$10) -> 45.194085 | E8: =C8*100/$B$1 -> 13.852691 | F8: =C8*IF(ISNUMBER(SEARCH("Labour",B8)),National!$L$4,IF(ISNUMBER(SEARCH("Conservative",B8)),National!$L$5,IF(OR(ISNUMBER(SEARCH("Reform",B8)),ISNUMBER(SEARCH("RefUK",B8))),National!$L$6,IF(ISNUMBER(SEARCH("Green",B8)),National!$L$7,IF(OR(ISNUMBER(SEARCH("Liberal Democrat",B8)),ISNUMBER(SEARCH("Lib Dem",B8))),National!$L$8,National!$L$9))))) -> 319.73077 | G8: =F8*100/$B$1 -> 9.0575289
A9: Matthews John Knott | B9: Green Party | C9: 37 | D9: =C9*100/SUM($C$7:$C$10) -> 3.4195933 | E9: =C9*100/$B$1 -> 1.0481586 | F9: =C9*IF(ISNUMBER(SEARCH("Labour",B9)),National!$L$4,IF(ISNUMBER(SEARCH("Conservative",B9)),National!$L$5,IF(OR(ISNUMBER(SEARCH("Reform",B9)),ISNUMBER(SEARCH("RefUK",B9))),National!$L$6,IF(ISNUMBER(SEARCH("Green",B9)),National!$L$7,IF(OR(ISNUMBER(SEARCH("Liberal Democrat",B9)),ISNUMBER(SEARCH("Lib Dem",B9))),National!$L$8,National!$L$9))))) -> 87.875 | G9: =F9*100/$B$1 -> 2.4893768
A10: Vivienne Parker (commonly known as Viv Parker) | B10: Liberal Democrats | C10: 344 | D10: =C10*100/SUM($C$7:$C$10) -> 31.792976 | E10: =C10*100/$B$1 -> 9.7450425 | F10: =C10*IF(ISNUMBER(SEARCH("Labour",B10)),National!$L$4,IF(ISNUMBER(SEARCH("Conservative",B10)),National!$L$5,IF(OR(ISNUMBER(SEARCH("Reform",B10)),ISNUMBER(SEARCH("RefUK",B10))),National!$L$6,IF(ISNUMBER(SEARCH("Green",B10)),National!$L$7,IF(OR(ISNUMBER(SEARCH("Liberal Democrat",B10)),ISNUMBER(SEARCH("Lib Dem",B10))),National!$L$8,National!$L$9))))) -> 481.6 | G10: =F10*100/$B$1 -> 13.643059

Sheet Fort Pitt
A1: Electorate (registered electors) | B1: 9170
A2: Councillors elected in ward | B2: 3
A3: Turnout | B3: 0.3374
A4: Blank / invalid ballots (rejected) | B4: 21
F5: prediction based in national swing since May 2023
A6: Candidate | B6: Party | C6: Votes | D6: % of votes | E6: % of electors | F6: votes | G6: % of electorate
A7: Smitha Campbell | B7: Labour and Co-operative Party | C7: 1726 | D7: =C7*100/SUM($C$7:$C$14) -> 20.086117 | E7: =C7*100/$B$1 -> 18.822246 | F7: =C7*IF(ISNUMBER(SEARCH("Labour",B7)),National!$L$4,IF(ISNUMBER(SEARCH("Conservative",B7)),National!$L$5,IF(OR(ISNUMBER(SEARCH("Reform",B7)),ISNUMBER(SEARCH("RefUK",B7))),National!$L$6,IF(ISNUMBER(SEARCH("Green",B7)),National!$L$7,IF(OR(ISNUMBER(SEARCH("Liberal Democrat",B7)),ISNUMBER(SEARCH("Lib Dem",B7))),National!$L$8,National!$L$9))))) -> 682.37209 | G7: =F7*100/$B$1 -> 7.4413532
A8: Harinder Singh Mahil | B8: Labour and Co-operative Party | C8: 1634 | D8: =C8*100/SUM($C$7:$C$14) -> 19.015478 | E8: =C8*100/$B$1 -> 17.818975 | F8: =C8*IF(ISNUMBER(SEARCH("Labour",B8)),National!$L$4,IF(ISNUMBER(SEARCH("Conservative",B8)),National!$L$5,IF(OR(ISNUMBER(SEARCH("Reform",B8)),ISNUMBER(SEARCH("RefUK",B8))),National!$L$6,IF(ISNUMBER(SEARCH("Green",B8)),National!$L$7,IF(OR(ISNUMBER(SEARCH("Liberal Democrat",B8)),ISNUMBER(SEARCH("Lib Dem",B8))),National!$L$8,National!$L$9))))) -> 646 | G8: =F8*100/$B$1 -> 7.044711
A9: Gareth Richard Myton | B9: Labour and Co-operative Party | C9: 1577 | D9: =C9*100/SUM($C$7:$C$14) -> 18.352147 | E9: =C9*100/$B$1 -> 17.197383 | F9: =C9*IF(ISNUMBER(SEARCH("Labour",B9)),National!$L$4,IF(ISNUMBER(SEARCH("Conservative",B9)),National!$L$5,IF(OR(ISNUMBER(SEARCH("Reform",B9)),ISNUMBER(SEARCH("RefUK",B9))),National!$L$6,IF(ISNUMBER(SEARCH("Green",B9)),National!$L$7,IF(OR(ISNUMBER(SEARCH("Liberal Democrat",B9)),ISNUMBER(SEARCH("Lib Dem",B9))),National!$L$8,National!$L$9))))) -> 623.46512 | G9: =F9*100/$B$1 -> 6.7989653
A10: Rupert David Fearon Turpin | B10: Local Conservatives | C10: 1028 | D10: =C10*100/SUM($C$7:$C$14) -> 11.963226 | E10: =C10*100/$B$1 -> 11.210469 | F10: =C10*IF(ISNUMBER(SEARCH("Labour",B10)),National!$L$4,IF(ISNUMBER(SEARCH("Conservative",B10)),National!$L$5,IF(OR(ISNUMBER(SEARCH("Reform",B10)),ISNUMBER(SEARCH("RefUK",B10))),National!$L$6,IF(ISNUMBER(SEARCH("Green",B10)),National!$L$7,IF(OR(ISNUMBER(SEARCH("Liberal Democrat",B10)),ISNUMBER(SEARCH("Lib Dem",B10))),National!$L$8,National!$L$9))))) -> 672.15385 | G10: =F10*100/$B$1 -> 7.329922
A11: Richard Niall Thorne | B11: Local Conservatives | C11: 951 | D11: =C11*100/SUM($C$7:$C$14) -> 11.067148 | E11: =C11*100/$B$1 -> 10.370774 | F11: =C11*IF(ISNUMBER(SEARCH("Labour",B11)),National!$L$4,IF(ISNUMBER(SEARCH("Conservative",B11)),National!$L$5,IF(OR(ISNUMBER(SEARCH("Reform",B11)),ISNUMBER(SEARCH("RefUK",B11))),National!$L$6,IF(ISNUMBER(SEARCH("Green",B11)),National!$L$7,IF(OR(ISNUMBER(SEARCH("Liberal Democrat",B11)),ISNUMBER(SEARCH("Lib Dem",B11))),National!$L$8,National!$L$9))))) -> 621.80769 | G11: =F11*100/$B$1 -> 6.7808909
A12: Gloria Blessing Chukwuka Opara | B12: Local Conservatives | C12: 901 | D12: =C12*100/SUM($C$7:$C$14) -> 10.485279 | E12: =C12*100/$B$1 -> 9.825518 | F12: =C12*IF(ISNUMBER(SEARCH("Labour",B12)),National!$L$4,IF(ISNUMBER(SEARCH("Conservative",B12)),National!$L$5,IF(OR(ISNUMBER(SEARCH("Reform",B12)),ISNUMBER(SEARCH("RefUK",B12))),National!$L$6,IF(ISNUMBER(SEARCH("Green",B12)),National!$L$7,IF(OR(ISNUMBER(SEARCH("Liberal Democrat",B12)),ISNUMBER(SEARCH("Lib Dem",B12))),National!$L$8,National!$L$9))))) -> 589.11538 | G12: =F12*100/$B$1 -> 6.4243771
A13: Karen Scott | B13: Green Party | C13: 527 | D13: =C13*100/SUM($C$7:$C$14) -> 6.1328989 | E13: =C13*100/$B$1 -> 5.7470011 | F13: =C13*IF(ISNUMBER(SEARCH("Labour",B13)),National!$L$4,IF(ISNUMBER(SEARCH("Conservative",B13)),National!$L$5,IF(OR(ISNUMBER(SEARCH("Reform",B13)),ISNUMBER(SEARCH("RefUK",B13))),National!$L$6,IF(ISNUMBER(SEARCH("Green",B13)),National!$L$7,IF(OR(ISNUMBER(SEARCH("Liberal Democrat",B13)),ISNUMBER(SEARCH("Lib Dem",B13))),National!$L$8,National!$L$9))))) -> 1251.625 | G13: =F13*100/$B$1 -> 13.649128
A14: Nirmal Sandhu | B14: Liberal Democrats | C14: 249 | D14: =C14*100/SUM($C$7:$C$14) -> 2.8977074 | E14: =C14*100/$B$1 -> 2.7153762 | F14: =C14*IF(ISNUMBER(SEARCH("Labour",B14)),National!$L$4,IF(ISNUMBER(SEARCH("Conservative",B14)),National!$L$5,IF(OR(ISNUMBER(SEARCH("Reform",B14)),ISNUMBER(SEARCH("RefUK",B14))),National!$L$6,IF(ISNUMBER(SEARCH("Green",B14)),National!$L$7,IF(OR(ISNUMBER(SEARCH("Liberal Democrat",B14)),ISNUMBER(SEARCH("Lib Dem",B14))),National!$L$8,National!$L$9))))) -> 348.6 | G14: =F14*100/$B$1 -> 3.8015267

Sheet Gillingham North
A1: Electorate (registered electors) | B1: 10237
A2: Councillors elected in ward | B2: 3
A3: Turnout | B3: 0.2175
A4: Blank / invalid ballots (rejected) | B4: 27
F5: prediction based in national swing since May 2023
A6: Candidate | B6: Party | C6: Votes | D6: % of votes | E6: % of electors | F6: votes | G6: % of electorate
A7: Adam Robert William Price | B7: Labour and Co-operative Party | C7: 1419 | D7: =C7*100/SUM($C$7:$C$14) -> 23.315807 | E7: =C7*100/$B$1 -> 13.861483 | F7: =C7*IF(ISNUMBER(SEARCH("Labour",B7)),National!$L$4,IF(ISNUMBER(SEARCH("Conservative",B7)),National!$L$5,IF(OR(ISNUMBER(SEARCH("Reform",B7)),ISNUMBER(SEARCH("RefUK",B7))),National!$L$6,IF(ISNUMBER(SEARCH("Green",B7)),National!$L$7,IF(OR(ISNUMBER(SEARCH("Liberal Democrat",B7)),ISNUMBER(SEARCH("Lib Dem",B7))),National!$L$8,National!$L$9))))) -> 561 | G7: =F7*100/$B$1 -> 5.4801211
A8: Douglas Kudakwashe Hamandishe | B8: Labour and Co-operative Party | C8: 1355 | D8: =C8*100/SUM($C$7:$C$14) -> 22.264213 | E8: =C8*100/$B$1 -> 13.2363 | F8: =C8*IF(ISNUMBER(SEARCH("Labour",B8)),National!$L$4,IF(ISNUMBER(SEARCH("Conservative",B8)),National!$L$5,IF(OR(ISNUMBER(SEARCH("Reform",B8)),ISNUMBER(SEARCH("RefUK",B8))),National!$L$6,IF(ISNUMBER(SEARCH("Green",B8)),National!$L$7,IF(OR(ISNUMBER(SEARCH("Liberal Democrat",B8)),ISNUMBER(SEARCH("Lib Dem",B8))),National!$L$8,National!$L$9))))) -> 535.69767 | G8: =F8*100/$B$1 -> 5.2329557
A9: Lia Helen Mandaracas | B9: Labour and Co-operative Party | C9: 1339 | D9: =C9*100/SUM($C$7:$C$14) -> 22.001314 | E9: =C9*100/$B$1 -> 13.080004 | F9: =C9*IF(ISNUMBER(SEARCH("Labour",B9)),National!$L$4,IF(ISNUMBER(SEARCH("Conservative",B9)),National!$L$5,IF(OR(ISNUMBER(SEARCH("Reform",B9)),ISNUMBER(SEARCH("RefUK",B9))),National!$L$6,IF(ISNUMBER(SEARCH("Green",B9)),National!$L$7,IF(OR(ISNUMBER(SEARCH("Liberal Democrat",B9)),ISNUMBER(SEARCH("Lib Dem",B9))),National!$L$8,National!$L$9))))) -> 529.37209 | G9: =F9*100/$B$1 -> 5.1711643
A10: Clayton Barrett | B10: Conservative Party candidate | C10: 530 | D10: =C10*100/SUM($C$7:$C$14) -> 8.7085113 | E10: =C10*100/$B$1 -> 5.177298 | F10: =C10*IF(ISNUMBER(SEARCH("Labour",B10)),National!$L$4,IF(ISNUMBER(SEARCH("Conservative",B10)),National!$L$5,IF(OR(ISNUMBER(SEARCH("Reform",B10)),ISNUMBER(SEARCH("RefUK",B10))),National!$L$6,IF(ISNUMBER(SEARCH("Green",B10)),National!$L$7,IF(OR(ISNUMBER(SEARCH("Liberal Democrat",B10)),ISNUMBER(SEARCH("Lib Dem",B10))),National!$L$8,National!$L$9))))) -> 346.53846 | G10: =F10*100/$B$1 -> 3.3851564
A11: Zarina Bibi Chishti | B11: Conservative Party candidate | C11: 439 | D11: =C11*100/SUM($C$7:$C$14) -> 7.2132764 | E11: =C11*100/$B$1 -> 4.2883657 | F11: =C11*IF(ISNUMBER(SEARCH("Labour",B11)),National!$L$4,IF(ISNUMBER(SEARCH("Conservative",B11)),National!$L$5,IF(OR(ISNUMBER(SEARCH("Reform",B11)),ISNUMBER(SEARCH("RefUK",B11))),National!$L$6,IF(ISNUMBER(SEARCH("Green",B11)),National!$L$7,IF(OR(ISNUMBER(SEARCH("Liberal Democrat",B11)),ISNUMBER(SEARCH("Lib Dem",B11))),National!$L$8,National!$L$9))))) -> 287.03846 | G11: =F11*100/$B$1 -> 2.8039314
A12: Harbans Singh Sidhu | B12: Conservative Party candidate | C12: 410 | D12: =C12*100/SUM($C$7:$C$14) -> 6.7367729 | E12: =C12*100/$B$1 -> 4.0050796 | F12: =C12*IF(ISNUMBER(SEARCH("Labour",B12)),National!$L$4,IF(ISNUMBER(SEARCH("Conservative",B12)),National!$L$5,IF(OR(ISNUMBER(SEARCH("Reform",B12)),ISNUMBER(SEARCH("RefUK",B12))),National!$L$6,IF(ISNUMBER(SEARCH("Green",B12)),National!$L$7,IF(OR(ISNUMBER(SEARCH("Liberal Democrat",B12)),ISNUMBER(SEARCH("Lib Dem",B12))),National!$L$8,National!$L$9))))) -> 268.07692 | G12: =F12*100/$B$1 -> 2.6187059
A13: Jeremy Spyby-Steanson | B13: Green Party | C13: 340 | D13: =C13*100/SUM($C$7:$C$14) -> 5.5865922 | E13: =C13*100/$B$1 -> 3.3212855 | F13: =C13*IF(ISNUMBER(SEARCH("Labour",B13)),National!$L$4,IF(ISNUMBER(SEARCH("Conservative",B13)),National!$L$5,IF(OR(ISNUMBER(SEARCH("Reform",B13)),ISNUMBER(SEARCH("RefUK",B13))),National!$L$6,IF(ISNUMBER(SEARCH("Green",B13)),National!$L$7,IF(OR(ISNUMBER(SEARCH("Liberal Democrat",B13)),ISNUMBER(SEARCH("Lib Dem",B13))),National!$L$8,National!$L$9))))) -> 807.5 | G13: =F13*100/$B$1 -> 7.8880531
A14: Ben Darryl Rist | B14: Liberal Democrats | C14: 254 | D14: =C14*100/SUM($C$7:$C$14) -> 4.173513 | E14: =C14*100/$B$1 -> 2.4811957 | F14: =C14*IF(ISNUMBER(SEARCH("Labour",B14)),National!$L$4,IF(ISNUMBER(SEARCH("Conservative",B14)),National!$L$5,IF(OR(ISNUMBER(SEARCH("Reform",B14)),ISNUMBER(SEARCH("RefUK",B14))),National!$L$6,IF(ISNUMBER(SEARCH("Green",B14)),National!$L$7,IF(OR(ISNUMBER(SEARCH("Liberal Democrat",B14)),ISNUMBER(SEARCH("Lib Dem",B14))),National!$L$8,National!$L$9))))) -> 355.6 | G14: =F14*100/$B$1 -> 3.4736739

Sheet Gillingham South
A1: Electorate (registered electors) | B1: 11085
A2: Councillors elected in ward | B2: 3
A3: Turnout | B3: 0.2235
A4: Blank / invalid ballots (rejected) | B4: 63
F5: prediction based in national swing since May 2023
A6: Candidate | B6: Party | C6: Votes | D6: % of votes | E6: % of electors | F6: votes | G6: % of electorate
A7: Rory Craig McDonald (commonly known as Dan McDonald) | B7: Labour and Co-operative Party | C7: 1617 | D7: =C7*100/SUM($C$7:$C$14) -> 24.181247 | E7: =C7*100/$B$1 -> 14.58728 | F7: =C7*IF(ISNUMBER(SEARCH("Labour",B7)),National!$L$4,IF(ISNUMBER(SEARCH("Conservative",B7)),National!$L$5,IF(OR(ISNUMBER(SEARCH("Reform",B7)),ISNUMBER(SEARCH("RefUK",B7))),National!$L$6,IF(ISNUMBER(SEARCH("Green",B7)),National!$L$7,IF(OR(ISNUMBER(SEARCH("Liberal Democrat",B7)),ISNUMBER(SEARCH("Lib Dem",B7))),National!$L$8,National!$L$9))))) -> 639.27907 | G7: =F7*100/$B$1 -> 5.7670642
A8: Naushabah Parveen Khan | B8: Labour and Co-operative Party | C8: 1531 | D8: =C8*100/SUM($C$7:$C$14) -> 22.89517 | E8: =C8*100/$B$1 -> 13.811457 | F8: =C8*IF(ISNUMBER(SEARCH("Labour",B8)),National!$L$4,IF(ISNUMBER(SEARCH("Conservative",B8)),National!$L$5,IF(OR(ISNUMBER(SEARCH("Reform",B8)),ISNUMBER(SEARCH("RefUK",B8))),National!$L$6,IF(ISNUMBER(SEARCH("Green",B8)),National!$L$7,IF(OR(ISNUMBER(SEARCH("Liberal Democrat",B8)),ISNUMBER(SEARCH("Lib Dem",B8))),National!$L$8,National!$L$9))))) -> 605.27907 | G8: =F8*100/$B$1 -> 5.4603434
A9: Louwella Margaret Prenter | B9: Labour and Co-operative Party | C9: 1491 | D9: =C9*100/SUM($C$7:$C$14) -> 22.296994 | E9: =C9*100/$B$1 -> 13.450609 | F9: =C9*IF(ISNUMBER(SEARCH("Labour",B9)),National!$L$4,IF(ISNUMBER(SEARCH("Conservative",B9)),National!$L$5,IF(OR(ISNUMBER(SEARCH("Reform",B9)),ISNUMBER(SEARCH("RefUK",B9))),National!$L$6,IF(ISNUMBER(SEARCH("Green",B9)),National!$L$7,IF(OR(ISNUMBER(SEARCH("Liberal Democrat",B9)),ISNUMBER(SEARCH("Lib Dem",B9))),National!$L$8,National!$L$9))))) -> 589.46512 | G9: =F9*100/$B$1 -> 5.3176826
A10: Amy Smith | B10: Conservative Party candidate | C10: 509 | D10: =C10*100/SUM($C$7:$C$14) -> 7.6117841 | E10: =C10*100/$B$1 -> 4.5917907 | F10: =C10*IF(ISNUMBER(SEARCH("Labour",B10)),National!$L$4,IF(ISNUMBER(SEARCH("Conservative",B10)),National!$L$5,IF(OR(ISNUMBER(SEARCH("Reform",B10)),ISNUMBER(SEARCH("RefUK",B10))),National!$L$6,IF(ISNUMBER(SEARCH("Green",B10)),National!$L$7,IF(OR(ISNUMBER(SEARCH("Liberal Democrat",B10)),ISNUMBER(SEARCH("Lib Dem",B10))),National!$L$8,National!$L$9))))) -> 332.80769 | G10: =F10*100/$B$1 -> 3.0023247
A11: Adenike Sijuwade Adeoye (commonly known as Siju Adeoye) | B11: Conservative Party candidate | C11: 471 | D11: =C11*100/SUM($C$7:$C$14) -> 7.0435173 | E11: =C11*100/$B$1 -> 4.2489851 | F11: =C11*IF(ISNUMBER(SEARCH("Labour",B11)),National!$L$4,IF(ISNUMBER(SEARCH("Conservative",B11)),National!$L$5,IF(OR(ISNUMBER(SEARCH("Reform",B11)),ISNUMBER(SEARCH("RefUK",B11))),National!$L$6,IF(ISNUMBER(SEARCH("Green",B11)),National!$L$7,IF(OR(ISNUMBER(SEARCH("Liberal Democrat",B11)),ISNUMBER(SEARCH("Lib Dem",B11))),National!$L$8,National!$L$9))))) -> 307.96154 | G11: =F11*100/$B$1 -> 2.7781826
A12: George Georghiou | B12: Conservative Party candidate | C12: 373 | D12: =C12*100/SUM($C$7:$C$14) -> 5.5779871 | E12: =C12*100/$B$1 -> 3.3649075 | F12: =C12*IF(ISNUMBER(SEARCH("Labour",B12)),National!$L$4,IF(ISNUMBER(SEARCH("Conservative",B12)),National!$L$5,IF(OR(ISNUMBER(SEARCH("Reform",B12)),ISNUMBER(SEARCH("RefUK",B12))),National!$L$6,IF(ISNUMBER(SEARCH("Green",B12)),National!$L$7,IF(OR(ISNUMBER(SEARCH("Liberal Democrat",B12)),ISNUMBER(SEARCH("Lib Dem",B12))),National!$L$8,National!$L$9))))) -> 243.88462 | G12: =F12*100/$B$1 -> 2.2001318
A13: Daniel Luis Belmonte | B13: Green Party | C13: 373 | D13: =C13*100/SUM($C$7:$C$14) -> 5.5779871 | E13: =C13*100/$B$1 -> 3.3649075 | F13: =C13*IF(ISNUMBER(SEARCH("Labour",B13)),National!$L$4,IF(ISNUMBER(SEARCH("Conservative",B13)),National!$L$5,IF(OR(ISNUMBER(SEARCH("Reform",B13)),ISNUMBER(SEARCH("RefUK",B13))),National!$L$6,IF(ISNUMBER(SEARCH("Green",B13)),National!$L$7,IF(OR(ISNUMBER(SEARCH("Liberal Democrat",B13)),ISNUMBER(SEARCH("Lib Dem",B13))),National!$L$8,National!$L$9))))) -> 885.875 | G13: =F13*100/$B$1 -> 7.9916554
A14: Christopher John Sams | B14: Liberal Democrats | C14: 322 | D14: =C14*100/SUM($C$7:$C$14) -> 4.8153133 | E14: =C14*100/$B$1 -> 2.9048263 | F14: =C14*IF(ISNUMBER(SEARCH("Labour",B14)),National!$L$4,IF(ISNUMBER(SEARCH("Conservative",B14)),National!$L$5,IF(OR(ISNUMBER(SEARCH("Reform",B14)),ISNUMBER(SEARCH("RefUK",B14))),National!$L$6,IF(ISNUMBER(SEARCH("Green",B14)),National!$L$7,IF(OR(ISNUMBER(SEARCH("Liberal Democrat",B14)),ISNUMBER(SEARCH("Lib Dem",B14))),National!$L$8,National!$L$9))))) -> 450.8 | G14: =F14*100/$B$1 -> 4.0667569

Sheet Hempstead & Wigmore
A1: Electorate (registered electors) | B1: 7463
A2: Councillors elected in ward | B2: 2
A3: Turnout | B3: 0.3511
A4: Blank / invalid ballots (rejected) | B4: 16
F5: prediction based in national swing since May 2023
A6: Candidate | B6: Party | C6: Votes | D6: % of votes | E6: % of electors | F6: votes | G6: % of electorate
A7: Lewis John William Bailey | B7: Labour Party | C7: 603 | D7: =C7*100/SUM($C$7:$C$14) -> 12.19167 | E7: =C7*100/$B$1 -> 8.0798606 | F7: =C7*IF(ISNUMBER(SEARCH("Labour",B7)),National!$L$4,IF(ISNUMBER(SEARCH("Conservative",B7)),National!$L$5,IF(OR(ISNUMBER(SEARCH("Reform",B7)),ISNUMBER(SEARCH("RefUK",B7))),National!$L$6,IF(ISNUMBER(SEARCH("Green",B7)),National!$L$7,IF(OR(ISNUMBER(SEARCH("Liberal Democrat",B7)),ISNUMBER(SEARCH("Lib Dem",B7))),National!$L$8,National!$L$9))))) -> 238.39535 | G7: =F7*100/$B$1 -> 3.1943635
A8: Haroon Ali Kahn | B8: Labour Party | C8: 450 | D8: =C8*100/SUM($C$7:$C$14) -> 9.0982612 | E8: =C8*100/$B$1 -> 6.0297468 | F8: =C8*IF(ISNUMBER(SEARCH("Labour",B8)),National!$L$4,IF(ISNUMBER(SEARCH("Conservative",B8)),National!$L$5,IF(OR(ISNUMBER(SEARCH("Reform",B8)),ISNUMBER(SEARCH("RefUK",B8))),National!$L$6,IF(ISNUMBER(SEARCH("Green",B8)),National!$L$7,IF(OR(ISNUMBER(SEARCH("Liberal Democrat",B8)),ISNUMBER(SEARCH("Lib Dem",B8))),National!$L$8,National!$L$9))))) -> 177.90698 | G8: =F8*100/$B$1 -> 2.3838534
A9: Jim Gilbourne (James Adrian Gilbourne; commonly known as Jim Gilbourne) | B9: Conservative Party candidate | C9: 1709 | D9: =C9*100/SUM($C$7:$C$14) -> 34.553174 | E9: =C9*100/$B$1 -> 22.899638 | F9: =C9*IF(ISNUMBER(SEARCH("Labour",B9)),National!$L$4,IF(ISNUMBER(SEARCH("Conservative",B9)),National!$L$5,IF(OR(ISNUMBER(SEARCH("Reform",B9)),ISNUMBER(SEARCH("RefUK",B9))),National!$L$6,IF(ISNUMBER(SEARCH("Green",B9)),National!$L$7,IF(OR(ISNUMBER(SEARCH("Liberal Democrat",B9)),ISNUMBER(SEARCH("Lib Dem",B9))),National!$L$8,National!$L$9))))) -> 1117.4231 | G9: =F9*100/$B$1 -> 14.97284
A10: Andrew William John Lawrence | B10: Conservative Party candidate | C10: 1617 | D10: =C10*100/SUM($C$7:$C$14) -> 32.693085 | E10: =C10*100/$B$1 -> 21.66689 | F10: =C10*IF(ISNUMBER(SEARCH("Labour",B10)),National!$L$4,IF(ISNUMBER(SEARCH("Conservative",B10)),National!$L$5,IF(OR(ISNUMBER(SEARCH("Reform",B10)),ISNUMBER(SEARCH("RefUK",B10))),National!$L$6,IF(ISNUMBER(SEARCH("Green",B10)),National!$L$7,IF(OR(ISNUMBER(SEARCH("Liberal Democrat",B10)),ISNUMBER(SEARCH("Lib Dem",B10))),National!$L$8,National!$L$9))))) -> 1057.2692 | G10: =F10*100/$B$1 -> 14.166813
A11: Kathryn Amanda Korff (commonly known as Kat Korff) | B11: Green Party | C11: 237 | D11: =C11*100/SUM($C$7:$C$14) -> 4.7917509 | E11: =C11*100/$B$1 -> 3.1756666 | F11: =C11*IF(ISNUMBER(SEARCH("Labour",B11)),National!$L$4,IF(ISNUMBER(SEARCH("Conservative",B11)),National!$L$5,IF(OR(ISNUMBER(SEARCH("Reform",B11)),ISNUMBER(SEARCH("RefUK",B11))),National!$L$6,IF(ISNUMBER(SEARCH("Green",B11)),National!$L$7,IF(OR(ISNUMBER(SEARCH("Liberal Democrat",B11)),ISNUMBER(SEARCH("Lib Dem",B11))),National!$L$8,National!$L$9))))) -> 562.875 | G11: =F11*100/$B$1 -> 7.5422082
A12: Daniele Erico Sergio Cavaliere (commonly known as Daniel Cavaliere) | B12: Liberal Democrats | C12: 222 | D12: =C12*100/SUM($C$7:$C$14) -> 4.4884755 | E12: =C12*100/$B$1 -> 2.9746751 | F12: =C12*IF(ISNUMBER(SEARCH("Labour",B12)),National!$L$4,IF(ISNUMBER(SEARCH("Conservative",B12)),National!$L$5,IF(OR(ISNUMBER(SEARCH("Reform",B12)),ISNUMBER(SEARCH("RefUK",B12))),National!$L$6,IF(ISNUMBER(SEARCH("Green",B12)),National!$L$7,IF(OR(ISNUMBER(SEARCH("Liberal Democrat",B12)),ISNUMBER(SEARCH("Lib Dem",B12))),National!$L$8,National!$L$9))))) -> 310.8 | G12: =F12*100/$B$1 -> 4.1645451
A13: Peter Anthony Wheeler | B13: Social Democratic Party | C13: 58 | D13: =C13*100/SUM($C$7:$C$14) -> 1.1726648 | E13: =C13*100/$B$1 -> 0.77716736 | F13: =C13*IF(ISNUMBER(SEARCH("Labour",B13)),National!$L$4,IF(ISNUMBER(SEARCH("Conservative",B13)),National!$L$5,IF(OR(ISNUMBER(SEARCH("Reform",B13)),ISNUMBER(SEARCH("RefUK",B13))),National!$L$6,IF(ISNUMBER(SEARCH("Green",B13)),National!$L$7,IF(OR(ISNUMBER(SEARCH("Liberal Democrat",B13)),ISNUMBER(SEARCH("Lib Dem",B13))),National!$L$8,National!$L$9))))) -> 66.285714 | G13: =F13*100/$B$1 -> 0.88819127
A14: John Wesley Gibson | B14: Christian Peoples Alliance | C14: 50 | D14: =C14*100/SUM($C$7:$C$14) -> 1.0109179 | E14: =C14*100/$B$1 -> 0.66997186 | F14: =C14*IF(ISNUMBER(SEARCH("Labour",B14)),National!$L$4,IF(ISNUMBER(SEARCH("Conservative",B14)),National!$L$5,IF(OR(ISNUMBER(SEARCH("Reform",B14)),ISNUMBER(SEARCH("RefUK",B14))),National!$L$6,IF(ISNUMBER(SEARCH("Green",B14)),National!$L$7,IF(OR(ISNUMBER(SEARCH("Liberal Democrat",B14)),ISNUMBER(SEARCH("Lib Dem",B14))),National!$L$8,National!$L$9))))) -> 57.142857 | G14: =F14*100/$B$1 -> 0.76568213

Sheet Hoo St W & High Halstow
A1: Electorate (registered electors) | B1: 10049
A2: Councillors elected in ward | B2: 3
A3: Turnout | B3: 0.3333
A4: Blank / invalid ballots (rejected) | B4: 9
F5: prediction based in national swing since May 2023
A6: Candidate | B6: Party | C6: Votes | D6: % of votes | E6: % of electors | F6: votes | G6: % of electorate
A7: Gary Barwell | B7: Labour Party | C7: 358 | D7: =C7*100/SUM($C$7:$C$18) -> 3.7831554 | E7: =C7*100/$B$1 -> 3.5625435 | F7: =C7*IF(ISNUMBER(SEARCH("Labour",B7)),National!$L$4,IF(ISNUMBER(SEARCH("Conservative",B7)),National!$L$5,IF(OR(ISNUMBER(SEARCH("Reform",B7)),ISNUMBER(SEARCH("RefUK",B7))),National!$L$6,IF(ISNUMBER(SEARCH("Green",B7)),National!$L$7,IF(OR(ISNUMBER(SEARCH("Liberal Democrat",B7)),ISNUMBER(SEARCH("Lib Dem",B7))),National!$L$8,National!$L$9))))) -> 141.53488 | G7: =F7*100/$B$1 -> 1.4084474
A8: Guiliana Paola Christmas | B8: Labour Party | C8: 336 | D8: =C8*100/SUM($C$7:$C$18) -> 3.550671 | E8: =C8*100/$B$1 -> 3.3436163 | F8: =C8*IF(ISNUMBER(SEARCH("Labour",B8)),National!$L$4,IF(ISNUMBER(SEARCH("Conservative",B8)),National!$L$5,IF(OR(ISNUMBER(SEARCH("Reform",B8)),ISNUMBER(SEARCH("RefUK",B8))),National!$L$6,IF(ISNUMBER(SEARCH("Green",B8)),National!$L$7,IF(OR(ISNUMBER(SEARCH("Liberal Democrat",B8)),ISNUMBER(SEARCH("Lib Dem",B8))),National!$L$8,National!$L$9))))) -> 132.83721 | G8: =F8*100/$B$1 -> 1.3218948
A9: Stephen Allan Vickery | B9: Labour Party | C9: 286 | D9: =C9*100/SUM($C$7:$C$18) -> 3.0222974 | E9: =C9*100/$B$1 -> 2.8460543 | F9: =C9*IF(ISNUMBER(SEARCH("Labour",B9)),National!$L$4,IF(ISNUMBER(SEARCH("Conservative",B9)),National!$L$5,IF(OR(ISNUMBER(SEARCH("Reform",B9)),ISNUMBER(SEARCH("RefUK",B9))),National!$L$6,IF(ISNUMBER(SEARCH("Green",B9)),National!$L$7,IF(OR(ISNUMBER(SEARCH("Liberal Democrat",B9)),ISNUMBER(SEARCH("Lib Dem",B9))),National!$L$8,National!$L$9))))) -> 113.06977 | G9: =F9*100/$B$1 -> 1.1251843
A10: Robert John Tildesley | B10: Local Conservatives | C10: 465 | D10: =C10*100/SUM($C$7:$C$18) -> 4.9138751 | E10: =C10*100/$B$1 -> 4.6273261 | F10: =C10*IF(ISNUMBER(SEARCH("Labour",B10)),National!$L$4,IF(ISNUMBER(SEARCH("Conservative",B10)),National!$L$5,IF(OR(ISNUMBER(SEARCH("Reform",B10)),ISNUMBER(SEARCH("RefUK",B10))),National!$L$6,IF(ISNUMBER(SEARCH("Green",B10)),National!$L$7,IF(OR(ISNUMBER(SEARCH("Liberal Democrat",B10)),ISNUMBER(SEARCH("Lib Dem",B10))),National!$L$8,National!$L$9))))) -> 304.03846 | G10: =F10*100/$B$1 -> 3.0255594
A11: Christopher John Sparks (commonly known as Chris Sparks) | B11: Local Conservatives | C11: 427 | D11: =C11*100/SUM($C$7:$C$18) -> 4.5123111 | E11: =C11*100/$B$1 -> 4.249179 | F11: =C11*IF(ISNUMBER(SEARCH("Labour",B11)),National!$L$4,IF(ISNUMBER(SEARCH("Conservative",B11)),National!$L$5,IF(OR(ISNUMBER(SEARCH("Reform",B11)),ISNUMBER(SEARCH("RefUK",B11))),National!$L$6,IF(ISNUMBER(SEARCH("Green",B11)),National!$L$7,IF(OR(ISNUMBER(SEARCH("Liberal Democrat",B11)),ISNUMBER(SEARCH("Lib Dem",B11))),National!$L$8,National!$L$9))))) -> 279.19231 | G11: =F11*100/$B$1 -> 2.7783094
A12: Fatima Mitchell | B12: Local Conservatives | C12: 409 | D12: =C12*100/SUM($C$7:$C$18) -> 4.3220966 | E12: =C12*100/$B$1 -> 4.0700567 | F12: =C12*IF(ISNUMBER(SEARCH("Labour",B12)),National!$L$4,IF(ISNUMBER(SEARCH("Conservative",B12)),National!$L$5,IF(OR(ISNUMBER(SEARCH("Reform",B12)),ISNUMBER(SEARCH("RefUK",B12))),National!$L$6,IF(ISNUMBER(SEARCH("Green",B12)),National!$L$7,IF(OR(ISNUMBER(SEARCH("Liberal Democrat",B12)),ISNUMBER(SEARCH("Lib Dem",B12))),National!$L$8,National!$L$9))))) -> 267.42308 | G12: =F12*100/$B$1 -> 2.6611909
A13: Julian Charles Sutton | B13: Green Party | C13: 140 | D13: =C13*100/SUM($C$7:$C$18) -> 1.4794463 | E13: =C13*100/$B$1 -> 1.3931735 | F13: =C13*IF(ISNUMBER(SEARCH("Labour",B13)),National!$L$4,IF(ISNUMBER(SEARCH("Conservative",B13)),National!$L$5,IF(OR(ISNUMBER(SEARCH("Reform",B13)),ISNUMBER(SEARCH("RefUK",B13))),National!$L$6,IF(ISNUMBER(SEARCH("Green",B13)),National!$L$7,IF(OR(ISNUMBER(SEARCH("Liberal Democrat",B13)),ISNUMBER(SEARCH("Lib Dem",B13))),National!$L$8,National!$L$9))))) -> 332.5 | G13: =F13*100/$B$1 -> 3.3087869
A14: Aaron Robert Sergejenkovs-Telford (commonly known as Aaron Sergejenkovs-Telford) | B14: Liberal Democrats | C14: 51 | D14: =C14*100/SUM($C$7:$C$18) -> 0.53894114 | E14: =C14*100/$B$1 -> 0.50751319 | F14: =C14*IF(ISNUMBER(SEARCH("Labour",B14)),National!$L$4,IF(ISNUMBER(SEARCH("Conservative",B14)),National!$L$5,IF(OR(ISNUMBER(SEARCH("Reform",B14)),ISNUMBER(SEARCH("RefUK",B14))),National!$L$6,IF(ISNUMBER(SEARCH("Green",B14)),National!$L$7,IF(OR(ISNUMBER(SEARCH("Liberal Democrat",B14)),ISNUMBER(SEARCH("Lib Dem",B14))),National!$L$8,National!$L$9))))) -> 71.4 | G14: =F14*100/$B$1 -> 0.71051846
A15: Steven John Hudson (commonly known as Steve Hudson) | B15: Reform UK | C15: 94 | D15: =C15*100/SUM($C$7:$C$18) -> 0.99334249 | E15: =C15*100/$B$1 -> 0.93541646 | F15: =C15*IF(ISNUMBER(SEARCH("Labour",B15)),National!$L$4,IF(ISNUMBER(SEARCH("Conservative",B15)),National!$L$5,IF(OR(ISNUMBER(SEARCH("Reform",B15)),ISNUMBER(SEARCH("RefUK",B15))),National!$L$6,IF(ISNUMBER(SEARCH("Green",B15)),National!$L$7,IF(OR(ISNUMBER(SEARCH("Liberal Democrat",B15)),ISNUMBER(SEARCH("Lib Dem",B15))),National!$L$8,National!$L$9))))) -> 391.66667 | G15: =F15*100/$B$1 -> 3.8975686
A16: George Josiah Thomas Crozer | B16: Independent | C16: 2388 | D16: =C16*100/SUM($C$7:$C$18) -> 25.235126 | E16: =C16*100/$B$1 -> 23.763559 | F16: =C16*IF(ISNUMBER(SEARCH("Labour",B16)),National!$L$4,IF(ISNUMBER(SEARCH("Conservative",B16)),National!$L$5,IF(OR(ISNUMBER(SEARCH("Reform",B16)),ISNUMBER(SEARCH("RefUK",B16))),National!$L$6,IF(ISNUMBER(SEARCH("Green",B16)),National!$L$7,IF(OR(ISNUMBER(SEARCH("Liberal Democrat",B16)),ISNUMBER(SEARCH("Lib Dem",B16))),National!$L$8,National!$L$9))))) -> 2729.1429 | G16: =F16*100/$B$1 -> 27.158353
A17: Ronald Philip Sands (commonly known as Ron Sands) | B17: Independent | C17: 2279 | D17: =C17*100/SUM($C$7:$C$18) -> 24.083272 | E17: =C17*100/$B$1 -> 22.678874 | F17: =C17*IF(ISNUMBER(SEARCH("Labour",B17)),National!$L$4,IF(ISNUMBER(SEARCH("Conservative",B17)),National!$L$5,IF(OR(ISNUMBER(SEARCH("Reform",B17)),ISNUMBER(SEARCH("RefUK",B17))),National!$L$6,IF(ISNUMBER(SEARCH("Green",B17)),National!$L$7,IF(OR(ISNUMBER(SEARCH("Liberal Democrat",B17)),ISNUMBER(SEARCH("Lib Dem",B17))),National!$L$8,National!$L$9))))) -> 2604.5714 | G17: =F17*100/$B$1 -> 25.918713
A18: Michael Ian Pearce | B18: Independent | C18: 2230 | D18: =C18*100/SUM($C$7:$C$18) -> 23.565465 | E18: =C18*100/$B$1 -> 22.191263 | F18: =C18*IF(ISNUMBER(SEARCH("Labour",B18)),National!$L$4,IF(ISNUMBER(SEARCH("Conservative",B18)),National!$L$5,IF(OR(ISNUMBER(SEARCH("Reform",B18)),ISNUMBER(SEARCH("RefUK",B18))),National!$L$6,IF(ISNUMBER(SEARCH("Green",B18)),National!$L$7,IF(OR(ISNUMBER(SEARCH("Liberal Democrat",B18)),ISNUMBER(SEARCH("Lib Dem",B18))),National!$L$8,National!$L$9))))) -> 2548.5714 | G18: =F18*100/$B$1 -> 25.361443

Sheet Lordswood & Walderslade
A1: Electorate (registered electors) | B1: 10857
A2: Councillors elected in ward | B2: 3
A3: Turnout | B3: 0.2758
A4: Blank / invalid ballots (rejected) | B4: 0
F5: prediction based in national swing since May 2023
A6: Candidate | B6: Party | C6: Votes | D6: % of votes | E6: % of electors | F6: votes | G6: % of electorate
A7: Christine Janice Godwin | B7: Labour Party | C7: 917 | D7: =C7*100/SUM($C$7:$C$14) -> 11.155718 | E7: =C7*100/$B$1 -> 8.4461638 | F7: =C7*IF(ISNUMBER(SEARCH("Labour",B7)),National!$L$4,IF(ISNUMBER(SEARCH("Conservative",B7)),National!$L$5,IF(OR(ISNUMBER(SEARCH("Reform",B7)),ISNUMBER(SEARCH("RefUK",B7))),National!$L$6,IF(ISNUMBER(SEARCH("Green",B7)),National!$L$7,IF(OR(ISNUMBER(SEARCH("Liberal Democrat",B7)),ISNUMBER(SEARCH("Lib Dem",B7))),National!$L$8,National!$L$9))))) -> 362.53488 | G7: =F7*100/$B$1 -> 3.339181
A8: David Alun Bowen | B8: Labour Party | C8: 817 | D8: =C8*100/SUM($C$7:$C$14) -> 9.9391727 | E8: =C8*100/$B$1 -> 7.525099 | F8: =C8*IF(ISNUMBER(SEARCH("Labour",B8)),National!$L$4,IF(ISNUMBER(SEARCH("Conservative",B8)),National!$L$5,IF(OR(ISNUMBER(SEARCH("Reform",B8)),ISNUMBER(SEARCH("RefUK",B8))),National!$L$6,IF(ISNUMBER(SEARCH("Green",B8)),National!$L$7,IF(OR(ISNUMBER(SEARCH("Liberal Democrat",B8)),ISNUMBER(SEARCH("Lib Dem",B8))),National!$L$8,National!$L$9))))) -> 323 | G8: =F8*100/$B$1 -> 2.9750391
A9: Brad Cook (Bradley Charles George Cook; commonly known as Brad Cook) | B9: Labour Party | C9: 777 | D9: =C9*100/SUM($C$7:$C$14) -> 9.4525547 | E9: =C9*100/$B$1 -> 7.1566731 | F9: =C9*IF(ISNUMBER(SEARCH("Labour",B9)),National!$L$4,IF(ISNUMBER(SEARCH("Conservative",B9)),National!$L$5,IF(OR(ISNUMBER(SEARCH("Reform",B9)),ISNUMBER(SEARCH("RefUK",B9))),National!$L$6,IF(ISNUMBER(SEARCH("Green",B9)),National!$L$7,IF(OR(ISNUMBER(SEARCH("Liberal Democrat",B9)),ISNUMBER(SEARCH("Lib Dem",B9))),National!$L$8,National!$L$9))))) -> 307.18605 | G9: =F9*100/$B$1 -> 2.8293824
A10: David Frederick Brake | B10: Local Conservatives | C10: 1752 | D10: =C10*100/SUM($C$7:$C$14) -> 21.313869 | E10: =C10*100/$B$1 -> 16.137054 | F10: =C10*IF(ISNUMBER(SEARCH("Labour",B10)),National!$L$4,IF(ISNUMBER(SEARCH("Conservative",B10)),National!$L$5,IF(OR(ISNUMBER(SEARCH("Reform",B10)),ISNUMBER(SEARCH("RefUK",B10))),National!$L$6,IF(ISNUMBER(SEARCH("Green",B10)),National!$L$7,IF(OR(ISNUMBER(SEARCH("Liberal Democrat",B10)),ISNUMBER(SEARCH("Lib Dem",B10))),National!$L$8,National!$L$9))))) -> 1145.5385 | G10: =F10*100/$B$1 -> 10.551151
A11: David Robert Wildey | B11: Local Conservatives | C11: 1728 | D11: =C11*100/SUM($C$7:$C$14) -> 21.021898 | E11: =C11*100/$B$1 -> 15.915999 | F11: =C11*IF(ISNUMBER(SEARCH("Labour",B11)),National!$L$4,IF(ISNUMBER(SEARCH("Conservative",B11)),National!$L$5,IF(OR(ISNUMBER(SEARCH("Reform",B11)),ISNUMBER(SEARCH("RefUK",B11))),National!$L$6,IF(ISNUMBER(SEARCH("Green",B11)),National!$L$7,IF(OR(ISNUMBER(SEARCH("Liberal Democrat",B11)),ISNUMBER(SEARCH("Lib Dem",B11))),National!$L$8,National!$L$9))))) -> 1129.8462 | G11: =F11*100/$B$1 -> 10.406615
A12: Adrian Victor Henry Gulvin | B12: Local Conservatives | C12: 1618 | D12: =C12*100/SUM($C$7:$C$14) -> 19.683698 | E12: =C12*100/$B$1 -> 14.902828 | F12: =C12*IF(ISNUMBER(SEARCH("Labour",B12)),National!$L$4,IF(ISNUMBER(SEARCH("Conservative",B12)),National!$L$5,IF(OR(ISNUMBER(SEARCH("Reform",B12)),ISNUMBER(SEARCH("RefUK",B12))),National!$L$6,IF(ISNUMBER(SEARCH("Green",B12)),National!$L$7,IF(OR(ISNUMBER(SEARCH("Liberal Democrat",B12)),ISNUMBER(SEARCH("Lib Dem",B12))),National!$L$8,National!$L$9))))) -> 1057.9231 | G12: =F12*100/$B$1 -> 9.7441566
A13: Sonia Lesley Hyner | B13: Green Party | C13: 339 | D13: =C13*100/SUM($C$7:$C$14) -> 4.1240876 | E13: =C13*100/$B$1 -> 3.1224095 | F13: =C13*IF(ISNUMBER(SEARCH("Labour",B13)),National!$L$4,IF(ISNUMBER(SEARCH("Conservative",B13)),National!$L$5,IF(OR(ISNUMBER(SEARCH("Reform",B13)),ISNUMBER(SEARCH("RefUK",B13))),National!$L$6,IF(ISNUMBER(SEARCH("Green",B13)),National!$L$7,IF(OR(ISNUMBER(SEARCH("Liberal Democrat",B13)),ISNUMBER(SEARCH("Lib Dem",B13))),National!$L$8,National!$L$9))))) -> 805.125 | G13: =F13*100/$B$1 -> 7.4157226
A14: Matthew William Vincent | B14: Liberal Democrats | C14: 272 | D14: =C14*100/SUM($C$7:$C$14) -> 3.3090024 | E14: =C14*100/$B$1 -> 2.5052961 | F14: =C14*IF(ISNUMBER(SEARCH("Labour",B14)),National!$L$4,IF(ISNUMBER(SEARCH("Conservative",B14)),National!$L$5,IF(OR(ISNUMBER(SEARCH("Reform",B14)),ISNUMBER(SEARCH("RefUK",B14))),National!$L$6,IF(ISNUMBER(SEARCH("Green",B14)),National!$L$7,IF(OR(ISNUMBER(SEARCH("Liberal Democrat",B14)),ISNUMBER(SEARCH("Lib Dem",B14))),National!$L$8,National!$L$9))))) -> 380.8 | G14: =F14*100/$B$1 -> 3.5074146

Sheet Luton
A1: Electorate (registered electors) | B1: 6871
A2: Councillors elected in ward | B2: 2
A3: Turnout | B3: 0.2235
A4: Blank / invalid ballots (rejected) | B4: 14
F5: prediction based in national swing since May 2023
A6: Candidate | B6: Party | C6: Votes | D6: % of votes | E6: % of electors | F6: votes | G6: % of electorate
A7: Simon Michael Curry | B7: Labour and Co-operative Party | C7: 796 | D7: =C7*100/SUM($C$7:$C$12) -> 27.372765 | E7: =C7*100/$B$1 -> 11.584922 | F7: =C7*IF(ISNUMBER(SEARCH("Labour",B7)),National!$L$4,IF(ISNUMBER(SEARCH("Conservative",B7)),National!$L$5,IF(OR(ISNUMBER(SEARCH("Reform",B7)),ISNUMBER(SEARCH("RefUK",B7))),National!$L$6,IF(ISNUMBER(SEARCH("Green",B7)),National!$L$7,IF(OR(ISNUMBER(SEARCH("Liberal Democrat",B7)),ISNUMBER(SEARCH("Lib Dem",B7))),National!$L$8,National!$L$9))))) -> 314.69767 | G7: =F7*100/$B$1 -> 4.5800855
A8: Jo Howcroft-Scott (Joanne Christine Howcroft-Scott; commonly known as Jo Howcroft-Scott) | B8: Labour and Co-operative Party | C8: 751 | D8: =C8*100/SUM($C$7:$C$12) -> 25.825309 | E8: =C8*100/$B$1 -> 10.929996 | F8: =C8*IF(ISNUMBER(SEARCH("Labour",B8)),National!$L$4,IF(ISNUMBER(SEARCH("Conservative",B8)),National!$L$5,IF(OR(ISNUMBER(SEARCH("Reform",B8)),ISNUMBER(SEARCH("RefUK",B8))),National!$L$6,IF(ISNUMBER(SEARCH("Green",B8)),National!$L$7,IF(OR(ISNUMBER(SEARCH("Liberal Democrat",B8)),ISNUMBER(SEARCH("Lib Dem",B8))),National!$L$8,National!$L$9))))) -> 296.90698 | G8: =F8*100/$B$1 -> 4.3211611
A9: Lulu Lammas (Marianna Hendrika Lammas; commonly known as Lulu Lammas) | B9: Conservative Party candidate | C9: 541 | D9: =C9*100/SUM($C$7:$C$12) -> 18.603851 | E9: =C9*100/$B$1 -> 7.873672 | F9: =C9*IF(ISNUMBER(SEARCH("Labour",B9)),National!$L$4,IF(ISNUMBER(SEARCH("Conservative",B9)),National!$L$5,IF(OR(ISNUMBER(SEARCH("Reform",B9)),ISNUMBER(SEARCH("RefUK",B9))),National!$L$6,IF(ISNUMBER(SEARCH("Green",B9)),National!$L$7,IF(OR(ISNUMBER(SEARCH("Liberal Democrat",B9)),ISNUMBER(SEARCH("Lib Dem",B9))),National!$L$8,National!$L$9))))) -> 353.73077 | G9: =F9*100/$B$1 -> 5.1481701
A10: Mos Igani (Mosueneme Igani; commonly known as Mos Igani) | B10: Conservative Party candidate | C10: 510 | D10: =C10*100/SUM($C$7:$C$12) -> 17.537827 | E10: =C10*100/$B$1 -> 7.4225004 | F10: =C10*IF(ISNUMBER(SEARCH("Labour",B10)),National!$L$4,IF(ISNUMBER(SEARCH("Conservative",B10)),National!$L$5,IF(OR(ISNUMBER(SEARCH("Reform",B10)),ISNUMBER(SEARCH("RefUK",B10))),National!$L$6,IF(ISNUMBER(SEARCH("Green",B10)),National!$L$7,IF(OR(ISNUMBER(SEARCH("Liberal Democrat",B10)),ISNUMBER(SEARCH("Lib Dem",B10))),National!$L$8,National!$L$9))))) -> 333.46154 | G10: =F10*100/$B$1 -> 4.8531733
A11: Debbie Sutton (Deborah Susan Sutton; commonly known as Debbie Sutton) | B11: Green Party | C11: 174 | D11: =C11*100/SUM($C$7:$C$12) -> 5.9834938 | E11: =C11*100/$B$1 -> 2.5323825 | F11: =C11*IF(ISNUMBER(SEARCH("Labour",B11)),National!$L$4,IF(ISNUMBER(SEARCH("Conservative",B11)),National!$L$5,IF(OR(ISNUMBER(SEARCH("Reform",B11)),ISNUMBER(SEARCH("RefUK",B11))),National!$L$6,IF(ISNUMBER(SEARCH("Green",B11)),National!$L$7,IF(OR(ISNUMBER(SEARCH("Liberal Democrat",B11)),ISNUMBER(SEARCH("Lib Dem",B11))),National!$L$8,National!$L$9))))) -> 413.25 | G11: =F11*100/$B$1 -> 6.0144084
A12: Paul Anthony O'Neill | B12: Liberal Democrats | C12: 136 | D12: =C12*100/SUM($C$7:$C$12) -> 4.6767538 | E12: =C12*100/$B$1 -> 1.9793334 | F12: =C12*IF(ISNUMBER(SEARCH("Labour",B12)),National!$L$4,IF(ISNUMBER(SEARCH("Conservative",B12)),National!$L$5,IF(OR(ISNUMBER(SEARCH("Reform",B12)),ISNUMBER(SEARCH("RefUK",B12))),National!$L$6,IF(ISNUMBER(SEARCH("Green",B12)),National!$L$7,IF(OR(ISNUMBER(SEARCH("Liberal Democrat",B12)),ISNUMBER(SEARCH("Lib Dem",B12))),National!$L$8,National!$L$9))))) -> 190.4 | G12: =F12*100/$B$1 -> 2.7710668

Sheet Princes Park
A1: Electorate (registered electors) | B1: 6645
A2: Councillors elected in ward | B2: 2
A3: Turnout | B3: 0.2439
A4: Blank / invalid ballots (rejected) | B4: 0
F5: prediction based in national swing since May 2023
A6: Candidate | B6: Party | C6: Votes | D6: % of votes | E6: % of electors | F6: votes | G6: % of electorate
A7: John Gower Strevens | B7: Labour Party | C7: 486 | D7: =C7*100/SUM($C$7:$C$12) -> 15.913556 | E7: =C7*100/$B$1 -> 7.3137698 | F7: =C7*IF(ISNUMBER(SEARCH("Labour",B7)),National!$L$4,IF(ISNUMBER(SEARCH("Conservative",B7)),National!$L$5,IF(OR(ISNUMBER(SEARCH("Reform",B7)),ISNUMBER(SEARCH("RefUK",B7))),National!$L$6,IF(ISNUMBER(SEARCH("Green",B7)),National!$L$7,IF(OR(ISNUMBER(SEARCH("Liberal Democrat",B7)),ISNUMBER(SEARCH("Lib Dem",B7))),National!$L$8,National!$L$9))))) -> 192.13953 | G7: =F7*100/$B$1 -> 2.8914904
A8: Temi Olodo (Temitope Omontanwa Olodo; commonly known as Temi Olodo) | B8: Labour Party | C8: 425 | D8: =C8*100/SUM($C$7:$C$12) -> 13.916176 | E8: =C8*100/$B$1 -> 6.3957863 | F8: =C8*IF(ISNUMBER(SEARCH("Labour",B8)),National!$L$4,IF(ISNUMBER(SEARCH("Conservative",B8)),National!$L$5,IF(OR(ISNUMBER(SEARCH("Reform",B8)),ISNUMBER(SEARCH("RefUK",B8))),National!$L$6,IF(ISNUMBER(SEARCH("Green",B8)),National!$L$7,IF(OR(ISNUMBER(SEARCH("Liberal Democrat",B8)),ISNUMBER(SEARCH("Lib Dem",B8))),National!$L$8,National!$L$9))))) -> 168.02326 | G8: =F8*100/$B$1 -> 2.5285667
A9: Robbie Lammas (Robert George Benedict Lammas; commonly known as Robbie Lammas) | B9: Conservative Party candidate | C9: 938 | D9: =C9*100/SUM($C$7:$C$12) -> 30.713818 | E9: =C9*100/$B$1 -> 14.115877 | F9: =C9*IF(ISNUMBER(SEARCH("Labour",B9)),National!$L$4,IF(ISNUMBER(SEARCH("Conservative",B9)),National!$L$5,IF(OR(ISNUMBER(SEARCH("Reform",B9)),ISNUMBER(SEARCH("RefUK",B9))),National!$L$6,IF(ISNUMBER(SEARCH("Green",B9)),National!$L$7,IF(OR(ISNUMBER(SEARCH("Liberal Democrat",B9)),ISNUMBER(SEARCH("Lib Dem",B9))),National!$L$8,National!$L$9))))) -> 613.30769 | G9: =F9*100/$B$1 -> 9.2296116
A10: Alex Hyne (Alexander Thomas Hyne; commonly known as Alex) | B10: Conservative Party candidate | C10: 933 | D10: =C10*100/SUM($C$7:$C$12) -> 30.550098 | E10: =C10*100/$B$1 -> 14.040632 | F10: =C10*IF(ISNUMBER(SEARCH("Labour",B10)),National!$L$4,IF(ISNUMBER(SEARCH("Conservative",B10)),National!$L$5,IF(OR(ISNUMBER(SEARCH("Reform",B10)),ISNUMBER(SEARCH("RefUK",B10))),National!$L$6,IF(ISNUMBER(SEARCH("Green",B10)),National!$L$7,IF(OR(ISNUMBER(SEARCH("Liberal Democrat",B10)),ISNUMBER(SEARCH("Lib Dem",B10))),National!$L$8,National!$L$9))))) -> 610.03846 | G10: =F10*100/$B$1 -> 9.1804133
A11: Simon Phillip Marchant | B11: Green Party | C11: 156 | D11: =C11*100/SUM($C$7:$C$12) -> 5.108055 | E11: =C11*100/$B$1 -> 2.3476298 | F11: =C11*IF(ISNUMBER(SEARCH("Labour",B11)),National!$L$4,IF(ISNUMBER(SEARCH("Conservative",B11)),National!$L$5,IF(OR(ISNUMBER(SEARCH("Reform",B11)),ISNUMBER(SEARCH("RefUK",B11))),National!$L$6,IF(ISNUMBER(SEARCH("Green",B11)),National!$L$7,IF(OR(ISNUMBER(SEARCH("Liberal Democrat",B11)),ISNUMBER(SEARCH("Lib Dem",B11))),National!$L$8,National!$L$9))))) -> 370.5 | G11: =F11*100/$B$1 -> 5.5756208
A12: Ian Christopher Sailes | B12: Liberal Democrats | C12: 116 | D12: =C12*100/SUM($C$7:$C$12) -> 3.7982973 | E12: =C12*100/$B$1 -> 1.7456734 | F12: =C12*IF(ISNUMBER(SEARCH("Labour",B12)),National!$L$4,IF(ISNUMBER(SEARCH("Conservative",B12)),National!$L$5,IF(OR(ISNUMBER(SEARCH("Reform",B12)),ISNUMBER(SEARCH("RefUK",B12))),National!$L$6,IF(ISNUMBER(SEARCH("Green",B12)),National!$L$7,IF(OR(ISNUMBER(SEARCH("Liberal Democrat",B12)),ISNUMBER(SEARCH("Lib Dem",B12))),National!$L$8,National!$L$9))))) -> 162.4 | G12: =F12*100/$B$1 -> 2.4439428

Sheet Rainham North
A1: Electorate (registered electors) | B1: 10341
A2: Councillors elected in ward | B2: 3
A3: Turnout | B3: 0.2873
A4: Blank / invalid ballots (rejected) | B4: 0
F5: prediction based in national swing since May 2023
A6: Candidate | B6: Party | C6: Votes | D6: % of votes | E6: % of electors | F6: votes | G6: % of electorate
A7: Mark Richard Harrison | B7: Labour Party | C7: 1025 | D7: =C7*100/SUM($C$7:$C$16) -> 12.512207 | E7: =C7*100/$B$1 -> 9.9120008 | F7: =C7*IF(ISNUMBER(SEARCH("Labour",B7)),National!$L$4,IF(ISNUMBER(SEARCH("Conservative",B7)),National!$L$5,IF(OR(ISNUMBER(SEARCH("Reform",B7)),ISNUMBER(SEARCH("RefUK",B7))),National!$L$6,IF(ISNUMBER(SEARCH("Green",B7)),National!$L$7,IF(OR(ISNUMBER(SEARCH("Liberal Democrat",B7)),ISNUMBER(SEARCH("Lib Dem",B7))),National!$L$8,National!$L$9))))) -> 405.23256 | G7: =F7*100/$B$1 -> 3.918698
A8: Nikita Morris (Nonchalonte Nikita Morris; commonly known as Nikita Morris) | B8: Labour Party | C8: 946 | D8: =C8*100/SUM($C$7:$C$16) -> 11.547852 | E8: =C8*100/$B$1 -> 9.1480514 | F8: =C8*IF(ISNUMBER(SEARCH("Labour",B8)),National!$L$4,IF(ISNUMBER(SEARCH("Conservative",B8)),National!$L$5,IF(OR(ISNUMBER(SEARCH("Reform",B8)),ISNUMBER(SEARCH("RefUK",B8))),National!$L$6,IF(ISNUMBER(SEARCH("Green",B8)),National!$L$7,IF(OR(ISNUMBER(SEARCH("Liberal Democrat",B8)),ISNUMBER(SEARCH("Lib Dem",B8))),National!$L$8,National!$L$9))))) -> 374 | G8: =F8*100/$B$1 -> 3.6166715
A9: Mutz Khan (Ahmed Mutahir Khan; commonly known as Mutz Khan) | B9: Labour Party | C9: 907 | D9: =C9*100/SUM($C$7:$C$16) -> 11.071777 | E9: =C9*100/$B$1 -> 8.7709119 | F9: =C9*IF(ISNUMBER(SEARCH("Labour",B9)),National!$L$4,IF(ISNUMBER(SEARCH("Conservative",B9)),National!$L$5,IF(OR(ISNUMBER(SEARCH("Reform",B9)),ISNUMBER(SEARCH("RefUK",B9))),National!$L$6,IF(ISNUMBER(SEARCH("Green",B9)),National!$L$7,IF(OR(ISNUMBER(SEARCH("Liberal Democrat",B9)),ISNUMBER(SEARCH("Lib Dem",B9))),National!$L$8,National!$L$9))))) -> 358.5814 | G9: =F9*100/$B$1 -> 3.4675698
A10: George Harry Perfect | B10: Conservative Party candidate | C10: 1210 | D10: =C10*100/SUM($C$7:$C$16) -> 14.770508 | E10: =C10*100/$B$1 -> 11.700996 | F10: =C10*IF(ISNUMBER(SEARCH("Labour",B10)),National!$L$4,IF(ISNUMBER(SEARCH("Conservative",B10)),National!$L$5,IF(OR(ISNUMBER(SEARCH("Reform",B10)),ISNUMBER(SEARCH("RefUK",B10))),National!$L$6,IF(ISNUMBER(SEARCH("Green",B10)),National!$L$7,IF(OR(ISNUMBER(SEARCH("Liberal Democrat",B10)),ISNUMBER(SEARCH("Lib Dem",B10))),National!$L$8,National!$L$9))))) -> 791.15385 | G10: =F10*100/$B$1 -> 7.6506513
A11: Wayne Ronald Spring | B11: Conservative Party candidate | C11: 1138 | D11: =C11*100/SUM($C$7:$C$16) -> 13.891602 | E11: =C11*100/$B$1 -> 11.004738 | F11: =C11*IF(ISNUMBER(SEARCH("Labour",B11)),National!$L$4,IF(ISNUMBER(SEARCH("Conservative",B11)),National!$L$5,IF(OR(ISNUMBER(SEARCH("Reform",B11)),ISNUMBER(SEARCH("RefUK",B11))),National!$L$6,IF(ISNUMBER(SEARCH("Green",B11)),National!$L$7,IF(OR(ISNUMBER(SEARCH("Liberal Democrat",B11)),ISNUMBER(SEARCH("Lib Dem",B11))),National!$L$8,National!$L$9))))) -> 744.07692 | G11: =F11*100/$B$1 -> 7.1954059
A12: Kwashie Amartei Anang | B12: Conservative Party candidate | C12: 1124 | D12: =C12*100/SUM($C$7:$C$16) -> 13.720703 | E12: =C12*100/$B$1 -> 10.869355 | F12: =C12*IF(ISNUMBER(SEARCH("Labour",B12)),National!$L$4,IF(ISNUMBER(SEARCH("Conservative",B12)),National!$L$5,IF(OR(ISNUMBER(SEARCH("Reform",B12)),ISNUMBER(SEARCH("RefUK",B12))),National!$L$6,IF(ISNUMBER(SEARCH("Green",B12)),National!$L$7,IF(OR(ISNUMBER(SEARCH("Liberal Democrat",B12)),ISNUMBER(SEARCH("Lib Dem",B12))),National!$L$8,National!$L$9))))) -> 734.92308 | G12: =F12*100/$B$1 -> 7.106886
A13: Trish Marchant (Patricia Anne Marchant; commonly known as Trish Marchant) | B13: Green Party | C13: 442 | D13: =C13*100/SUM($C$7:$C$16) -> 5.3955078 | E13: =C13*100/$B$1 -> 4.2742481 | F13: =C13*IF(ISNUMBER(SEARCH("Labour",B13)),National!$L$4,IF(ISNUMBER(SEARCH("Conservative",B13)),National!$L$5,IF(OR(ISNUMBER(SEARCH("Reform",B13)),ISNUMBER(SEARCH("RefUK",B13))),National!$L$6,IF(ISNUMBER(SEARCH("Green",B13)),National!$L$7,IF(OR(ISNUMBER(SEARCH("Liberal Democrat",B13)),ISNUMBER(SEARCH("Lib Dem",B13))),National!$L$8,National!$L$9))))) -> 1049.75 | G13: =F13*100/$B$1 -> 10.151339
A14: Stuart James Bourne | B14: Liberal Democrats | C14: 675 | D14: =C14*100/SUM($C$7:$C$16) -> 8.2397461 | E14: =C14*100/$B$1 -> 6.5274151 | F14: =C14*IF(ISNUMBER(SEARCH("Labour",B14)),National!$L$4,IF(ISNUMBER(SEARCH("Conservative",B14)),National!$L$5,IF(OR(ISNUMBER(SEARCH("Reform",B14)),ISNUMBER(SEARCH("RefUK",B14))),National!$L$6,IF(ISNUMBER(SEARCH("Green",B14)),National!$L$7,IF(OR(ISNUMBER(SEARCH("Liberal Democrat",B14)),ISNUMBER(SEARCH("Lib Dem",B14))),National!$L$8,National!$L$9))))) -> 945 | G14: =F14*100/$B$1 -> 9.1383812
A15: Rosell Alan William Collins | B15: Liberal Democrats | C15: 402 | D15: =C15*100/SUM($C$7:$C$16) -> 4.9072266 | E15: =C15*100/$B$1 -> 3.8874384 | F15: =C15*IF(ISNUMBER(SEARCH("Labour",B15)),National!$L$4,IF(ISNUMBER(SEARCH("Conservative",B15)),National!$L$5,IF(OR(ISNUMBER(SEARCH("Reform",B15)),ISNUMBER(SEARCH("RefUK",B15))),National!$L$6,IF(ISNUMBER(SEARCH("Green",B15)),National!$L$7,IF(OR(ISNUMBER(SEARCH("Liberal Democrat",B15)),ISNUMBER(SEARCH("Lib Dem",B15))),National!$L$8,National!$L$9))))) -> 562.8 | G15: =F15*100/$B$1 -> 5.4424137
A16: Nicholas Chan (Yu Hin Nick Chan; commonly known as Nicholas Chan) | B16: Liberal Democrats | C16: 323 | D16: =C16*100/SUM($C$7:$C$16) -> 3.9428711 | E16: =C16*100/$B$1 -> 3.123489 | F16: =C16*IF(ISNUMBER(SEARCH("Labour",B16)),National!$L$4,IF(ISNUMBER(SEARCH("Conservative",B16)),National!$L$5,IF(OR(ISNUMBER(SEARCH("Reform",B16)),ISNUMBER(SEARCH("RefUK",B16))),National!$L$6,IF(ISNUMBER(SEARCH("Green",B16)),National!$L$7,IF(OR(ISNUMBER(SEARCH("Liberal Democrat",B16)),ISNUMBER(SEARCH("Lib Dem",B16))),National!$L$8,National!$L$9))))) -> 452.2 | G16: =F16*100/$B$1 -> 4.3728846

Sheet Rainham South East
A1: Electorate (registered electors) | B1: 10466
A2: Councillors elected in ward | B2: 3
A3: Turnout | B3: 0.2715
